Workbook

Sheet ATTENDANCE
A1: AYV INFRASTRUCTURE
A2: ATTENDANCE REPORT
A3: NOTE: ONLY MAKE EDIT IN THE YELLOW COLOURED CELL'S | N3: SEPTEMBER | P3: 2026
A4: {=INDEX(EMPLOYEE_LIST!$A:$A,INT((ROW()-4)/7)+2)} -> AMAN NAYAK | D4: =IF(A4="", "", IFERROR(VLOOKUP(A4, EMPLOYEE_LIST!$A:$H, 2, FALSE), "")) -> AYV-35 | H4: =IF(A4="", "", IFERROR(VLOOKUP(A4, EMPLOYEE_LIST!$A:$H, 3, FALSE), "")) -> ENGINEERING | L4: =IF(A4="", "", IFERROR(VLOOKUP(A4, EMPLOYEE_LIST!$A:$H, 4, FALSE), "")) -> SUPERVISOR | P4: =IF($A4="", "", "Full Day: " & COUNTIF(B9:AF9, "FD")) -> Full Day: 0 | S4: =IF($A4="", "", "HALF Day: " & COUNTIF(B9:AF9, "HD")) -> HALF Day: 0 | V4: =IF($A4="", "", "ABSENT: " & COUNTIF(B9:AF9, "A")) -> ABSENT: 10 | Y4: =IF($A4="", "", "WEEK OFF: " & COUNTIF(B9:AF9, "WO")) -> WEEK OFF: 1 | AB4: =IF($A4="", "", "LEAVE: " & COUNTIF(B9:AF9, "L")) -> LEAVE: 0 | AD4: =IF($A4="", "", "HOLIDAY: " & COUNTIF(B9:AF9, "HL")) -> HOLIDAY: 0
A5: =IF($A4="", "", "DATE") -> DATE | B5: {=IF($A4="","",LET(mNum,MONTH(1&$N$3),start,DATE($P$3,mNum,1),days,DAY(EOMONTH(start,0)),MAP(SEQUENCE(1,days,0),LAMBDA(n,UPPER(TEXT(start+n,"dd (ddd)"))))))} -> 01 (TUE) | C5: 02 (WED) | D5: 03 (THU) | E5: 04 (FRI) | F5: 05 (SAT) | G5: 06 (SUN) | H5: 07 (MON) | I5: 08 (TUE) | J5: 09 (WED) | K5: 10 (THU) | L5: 11 (FRI) | M5: 12 (SAT) | N5: 13 (SUN) | O5: 14 (MON) | P5: 15 (TUE) | Q5: 16 (WED) | R5: 17 (THU) | S5: 18 (FRI) | T5: 19 (SAT) | U5: 20 (SUN) | V5: 21 (MON) | W5: 22 (TUE) | X5: 23 (WED) | Y5: 24 (THU) | Z5: 25 (FRI) | AA5: 26 (SAT) | AB5: 27 (SUN) | AC5: 28 (MON) | AD5: 29 (TUE) | AE5: 30 (WED)
A6: =IF($A4="", "", "IN") -> IN | B6: {=IF(OR($A4="",B$5=""),"",IFNA(INDEX(DATA_LOG!$C:$C,MATCH(1,(DATA_LOG!$A:$A=$A4)*(TEXT(DATA_LOG!$B:$B,"yyyy-MM-dd")=TEXT(DATE($P$3,MONTH(1&$N$3),VALUE(LEFT(B$5,2))),"yyyy-MM-dd")),0)),""))} | C6: {=IF(OR($A4="",C$5=""),"",IFNA(INDEX(DATA_LOG!$C:$C,MATCH(1,(DATA_LOG!$A:$A=$A4)*(TEXT(DATA_LOG!$B:$B,"yyyy-MM-dd")=TEXT(DATE($P$3,MONTH(1&$N$3),VALUE(LEFT(C$5,2))),"yyyy-MM-dd")),0)),""))} | D6: {=IF(OR($A4="",D$5=""),"",IFNA(INDEX(DATA_LOG!$C:$C,MATCH(1,(DATA_LOG!$A:$A=$A4)*(TEXT(DATA_LOG!$B:$B,"yyyy-MM-dd")=TEXT(DATE($P$3,MONTH(1&$N$3),VALUE(LEFT(D$5,2))),"yyyy-MM-dd")),0)),""))} | E6: {=IF(OR($A4="",E$5=""),"",IFNA(INDEX(DATA_LOG!$C:$C,MATCH(1,(DATA_LOG!$A:$A=$A4)*(TEXT(DATA_LOG!$B:$B,"yyyy-MM-dd")=TEXT(DATE($P$3,MONTH(1&$N$3),VALUE(LEFT(E$5,2))),"yyyy-MM-dd")),0)),""))} | F6: {=IF(OR($A4="",F$5=""),"",IFNA(INDEX(DATA_LOG!$C:$C,MATCH(1,(DATA_LOG!$A:$A=$A4)*(TEXT(DATA_LOG!$B:$B,"yyyy-MM-dd")=TEXT(DATE($P$3,MONTH(1&$N$3),VALUE(LEFT(F$5,2))),"yyyy-MM-dd")),0)),""))} | G6: {=IF(OR($A4="",G$5=""),"",IFNA(INDEX(DATA_LOG!$C:$C,MATCH(1,(DATA_LOG!$A:$A=$A4)*(TEXT(DATA_LOG!$B:$B,"yyyy-MM-dd")=TEXT(DATE($P$3,MONTH(1&$N$3),VALUE(LEFT(G$5,2))),"yyyy-MM-dd")),0)),""))} | H6: {=IF(OR($A4="",H$5=""),"",IFNA(INDEX(DATA_LOG!$C:$C,MATCH(1,(DATA_LOG!$A:$A=$A4)*(TEXT(DATA_LOG!$B:$B,"yyyy-MM-dd")=TEXT(DATE($P$3,MONTH(1&$N$3),VALUE(LEFT(H$5,2))),"yyyy-MM-dd")),0)),""))} | I6: {=IF(OR($A4="",I$5=""),"",IFNA(INDEX(DATA_LOG!$C:$C,MATCH(1,(DATA_LOG!$A:$A=$A4)*(TEXT(DATA_LOG!$B:$B,"yyyy-MM-dd")=TEXT(DATE($P$3,MONTH(1&$N$3),VALUE(LEFT(I$5,2))),"yyyy-MM-dd")),0)),""))} | ... AF6: {=IF(OR($A4="",AF$5=""),"",IFNA(INDEX(DATA_LOG!$C:$C,MATCH(1,(DATA_LOG!$A:$A=$A4)*(TEXT(DATA_LOG!$B:$B,"yyyy-MM-dd")=TEXT(DATE($P$3,MONTH(1&$N$3),VALUE(LEFT(AF$5,2))),"yyyy-MM-dd")),0)),""))}
A7: =IF($A4="", "", "OUT") -> OUT | B7: {=IF(OR($A4="",B$5=""),"",IFNA(INDEX(DATA_LOG!$D:$D,MATCH(1,(DATA_LOG!$A:$A=$A4)*(TEXT(DATA_LOG!$B:$B,"yyyy-MM-dd")=TEXT(DATE($P$3,MONTH(1&$N$3),VALUE(LEFT(B$5,2))),"yyyy-MM-dd")),0)),""))} | C7: {=IF(OR($A4="",C$5=""),"",IFNA(INDEX(DATA_LOG!$D:$D,MATCH(1,(DATA_LOG!$A:$A=$A4)*(TEXT(DATA_LOG!$B:$B,"yyyy-MM-dd")=TEXT(DATE($P$3,MONTH(1&$N$3),VALUE(LEFT(C$5,2))),"yyyy-MM-dd")),0)),""))} | D7: {=IF(OR($A4="",D$5=""),"",IFNA(INDEX(DATA_LOG!$D:$D,MATCH(1,(DATA_LOG!$A:$A=$A4)*(TEXT(DATA_LOG!$B:$B,"yyyy-MM-dd")=TEXT(DATE($P$3,MONTH(1&$N$3),VALUE(LEFT(D$5,2))),"yyyy-MM-dd")),0)),""))} | E7: {=IF(OR($A4="",E$5=""),"",IFNA(INDEX(DATA_LOG!$D:$D,MATCH(1,(DATA_LOG!$A:$A=$A4)*(TEXT(DATA_LOG!$B:$B,"yyyy-MM-dd")=TEXT(DATE($P$3,MONTH(1&$N$3),VALUE(LEFT(E$5,2))),"yyyy-MM-dd")),0)),""))} | F7: {=IF(OR($A4="",F$5=""),"",IFNA(INDEX(DATA_LOG!$D:$D,MATCH(1,(DATA_LOG!$A:$A=$A4)*(TEXT(DATA_LOG!$B:$B,"yyyy-MM-dd")=TEXT(DATE($P$3,MONTH(1&$N$3),VALUE(LEFT(F$5,2))),"yyyy-MM-dd")),0)),""))} | G7: {=IF(OR($A4="",G$5=""),"",IFNA(INDEX(DATA_LOG!$D:$D,MATCH(1,(DATA_LOG!$A:$A=$A4)*(TEXT(DATA_LOG!$B:$B,"yyyy-MM-dd")=TEXT(DATE($P$3,MONTH(1&$N$3),VALUE(LEFT(G$5,2))),"yyyy-MM-dd")),0)),""))} | H7: {=IF(OR($A4="",H$5=""),"",IFNA(INDEX(DATA_LOG!$D:$D,MATCH(1,(DATA_LOG!$A:$A=$A4)*(TEXT(DATA_LOG!$B:$B,"yyyy-MM-dd")=TEXT(DATE($P$3,MONTH(1&$N$3),VALUE(LEFT(H$5,2))),"yyyy-MM-dd")),0)),""))} | I7: {=IF(OR($A4="",I$5=""),"",IFNA(INDEX(DATA_LOG!$D:$D,MATCH(1,(DATA_LOG!$A:$A=$A4)*(TEXT(DATA_LOG!$B:$B,"yyyy-MM-dd")=TEXT(DATE($P$3,MONTH(1&$N$3),VALUE(LEFT(I$5,2))),"yyyy-MM-dd")),0)),""))} | ... AF7: {=IF(OR($A4="",AF$5=""),"",IFNA(INDEX(DATA_LOG!$D:$D,MATCH(1,(DATA_LOG!$A:$A=$A4)*(TEXT(DATA_LOG!$B:$B,"yyyy-MM-dd")=TEXT(DATE($P$3,MONTH(1&$N$3),VALUE(LEFT(AF$5,2))),"yyyy-MM-dd")),0)),""))}
A8: =IF($A4="", "", "TOTAL") -> TOTAL | B8: =IF(AND(B62<>"",B63<>""),TEXT(MOD(B63-B62,1),"hh:mm"),"") | C8: =IF(AND(C62<>"",C63<>""),TEXT(MOD(C63-C62,1),"hh:mm"),"") | D8: =IF(AND(D62<>"",D63<>""),TEXT(MOD(D63-D62,1),"hh:mm"),"") | E8: =IF(AND(E62<>"",E63<>""),TEXT(MOD(E63-E62,1),"hh:mm"),"") | F8: =IF(AND(F62<>"",F63<>""),TEXT(MOD(F63-F62,1),"hh:mm"),"") | G8: =IF(AND(G62<>"",G63<>""),TEXT(MOD(G63-G62,1),"hh:mm"),"") | H8: =IF(AND(H62<>"",H63<>""),TEXT(MOD(H63-H62,1),"hh:mm"),"") | I8: =IF(AND(I62<>"",I63<>""),TEXT(MOD(I63-I62,1),"hh:mm"),"") | ... AF8: =IF(AND(AF62<>"",AF63<>""),TEXT(MOD(AF63-AF62,1),"hh:mm"),"")
A9: =IF($A4="", "", "STATUS") -> STATUS | B9: =IFERROR(__xludf.DUMMYFUNCTION("IF($A4="""","""",IF(B$5="""","""",LET(logStatus,IFNA(INDEX(DATA_LOG!$E:$E,MATCH(1,(DATA_LOG!$A:$A=$A4)*(TEXT(DATA_LOG!$B:$B,""yyyy-MM-dd"")=TEXT(DATE($P$3,MONTH(1&$N$3),VALUE(LEFT(B$5,2))),""yyyy-MM-dd"")),0)),""""),selectedDate,DATE($P$3,MONTH(1&$N$3),VA"&"LUE(LEFT(B$5,2))),IF(logStatus<>"""",UPPER(logStatus),IF(selectedDate>TODAY(),""-"",IF(REGEXMATCH(B$5,""SUN""),""WO"",IF(B$8<>"""",IF(VALUE(B$8)>=9/24,""FD"",""HD""),""A"")))))))"),"A") -> A | C9: =IFERROR(__xludf.DUMMYFUNCTION("IF($A4="""","""",IF(C$5="""","""",LET(logStatus,IFNA(INDEX(DATA_LOG!$E:$E,MATCH(1,(DATA_LOG!$A:$A=$A4)*(TEXT(DATA_LOG!$B:$B,""yyyy-MM-dd"")=TEXT(DATE($P$3,MONTH(1&$N$3),VALUE(LEFT(C$5,2))),""yyyy-MM-dd"")),0)),""""),selectedDate,DATE($P$3,MONTH(1&$N$3),VA"&"LUE(LEFT(C$5,2))),IF(logStatus<>"""",UPPER(logStatus),IF(selectedDate>TODAY(),""-"",IF(REGEXMATCH(C$5,""SUN""),""WO"",IF(C$8<>"""",IF(VALUE(C$8)>=9/24,""FD"",""HD""),""A"")))))))"),"A") -> A | D9: =IFERROR(__xludf.DUMMYFUNCTION("IF($A4="""","""",IF(D$5="""","""",LET(logStatus,IFNA(INDEX(DATA_LOG!$E:$E,MATCH(1,(DATA_LOG!$A:$A=$A4)*(TEXT(DATA_LOG!$B:$B,""yyyy-MM-dd"")=TEXT(DATE($P$3,MONTH(1&$N$3),VALUE(LEFT(D$5,2))),""yyyy-MM-dd"")),0)),""""),selectedDate,DATE($P$3,MONTH(1&$N$3),VA"&"LUE(LEFT(D$5,2))),IF(logStatus<>"""",UPPER(logStatus),IF(selectedDate>TODAY(),""-"",IF(REGEXMATCH(D$5,""SUN""),""WO"",IF(D$8<>"""",IF(VALUE(D$8)>=9/24,""FD"",""HD""),""A"")))))))"),"A") -> A | E9: =IFERROR(__xludf.DUMMYFUNCTION("IF($A4="""","""",IF(E$5="""","""",LET(logStatus,IFNA(INDEX(DATA_LOG!$E:$E,MATCH(1,(DATA_LOG!$A:$A=$A4)*(TEXT(DATA_LOG!$B:$B,""yyyy-MM-dd"")=TEXT(DATE($P$3,MONTH(1&$N$3),VALUE(LEFT(E$5,2))),""yyyy-MM-dd"")),0)),""""),selectedDate,DATE($P$3,MONTH(1&$N$3),VA"&"LUE(LEFT(E$5,2))),IF(logStatus<>"""",UPPER(logStatus),IF(selectedDate>TODAY(),""-"",IF(REGEXMATCH(E$5,""SUN""),""WO"",IF(E$8<>"""",IF(VALUE(E$8)>=9/24,""FD"",""HD""),""A"")))))))"),"A") -> A | F9: =IFERROR(__xludf.DUMMYFUNCTION("IF($A4="""","""",IF(F$5="""","""",LET(logStatus,IFNA(INDEX(DATA_LOG!$E:$E,MATCH(1,(DATA_LOG!$A:$A=$A4)*(TEXT(DATA_LOG!$B:$B,""yyyy-MM-dd"")=TEXT(DATE($P$3,MONTH(1&$N$3),VALUE(LEFT(F$5,2))),""yyyy-MM-dd"")),0)),""""),selectedDate,DATE($P$3,MONTH(1&$N$3),VA"&"LUE(LEFT(F$5,2))),IF(logStatus<>"""",UPPER(logStatus),IF(selectedDate>TODAY(),""-"",IF(REGEXMATCH(F$5,""SUN""),""WO"",IF(F$8<>"""",IF(VALUE(F$8)>=9/24,""FD"",""HD""),""A"")))))))"),"A") -> A | G9: =IFERROR(__xludf.DUMMYFUNCTION("IF($A4="""","""",IF(G$5="""","""",LET(logStatus,IFNA(INDEX(DATA_LOG!$E:$E,MATCH(1,(DATA_LOG!$A:$A=$A4)*(TEXT(DATA_LOG!$B:$B,""yyyy-MM-dd"")=TEXT(DATE($P$3,MONTH(1&$N$3),VALUE(LEFT(G$5,2))),""yyyy-MM-dd"")),0)),""""),selectedDate,DATE($P$3,MONTH(1&$N$3),VA"&"LUE(LEFT(G$5,2))),IF(logStatus<>"""",UPPER(logStatus),IF(selectedDate>TODAY(),""-"",IF(REGEXMATCH(G$5,""SUN""),""WO"",IF(G$8<>"""",IF(VALUE(G$8)>=9/24,""FD"",""HD""),""A"")))))))"),"WO") -> WO | H9: =IFERROR(__xludf.DUMMYFUNCTION("IF($A4="""","""",IF(H$5="""","""",LET(logStatus,IFNA(INDEX(DATA_LOG!$E:$E,MATCH(1,(DATA_LOG!$A:$A=$A4)*(TEXT(DATA_LOG!$B:$B,""yyyy-MM-dd"")=TEXT(DATE($P$3,MONTH(1&$N$3),VALUE(LEFT(H$5,2))),""yyyy-MM-dd"")),0)),""""),selectedDate,DATE($P$3,MONTH(1&$N$3),VA"&"LUE(LEFT(H$5,2))),IF(logStatus<>"""",UPPER(logStatus),IF(selectedDate>TODAY(),""-"",IF(REGEXMATCH(H$5,""SUN""),""WO"",IF(H$8<>"""",IF(VALUE(H$8)>=9/24,""FD"",""HD""),""A"")))))))"),"A") -> A | I9: =IFERROR(__xludf.DUMMYFUNCTION("IF($A4="""","""",IF(I$5="""","""",LET(logStatus,IFNA(INDEX(DATA_LOG!$E:$E,MATCH(1,(DATA_LOG!$A:$A=$A4)*(TEXT(DATA_LOG!$B:$B,""yyyy-MM-dd"")=TEXT(DATE($P$3,MONTH(1&$N$3),VALUE(LEFT(I$5,2))),""yyyy-MM-dd"")),0)),""""),selectedDate,DATE($P$3,MONTH(1&$N$3),VA"&"LUE(LEFT(I$5,2))),IF(logStatus<>"""",UPPER(logStatus),IF(selectedDate>TODAY(),""-"",IF(REGEXMATCH(I$5,""SUN""),""WO"",IF(I$8<>"""",IF(VALUE(I$8)>=9/24,""FD"",""HD""),""A"")))))))"),"A") -> A | J9: =IFERROR(__xludf.DUMMYFUNCTION("IF($A4="""","""",IF(J$5="""","""",LET(logStatus,IFNA(INDEX(DATA_LOG!$E:$E,MATCH(1,(DATA_LOG!$A:$A=$A4)*(TEXT(DATA_LOG!$B:$B,""yyyy-MM-dd"")=TEXT(DATE($P$3,MONTH(1&$N$3),VALUE(LEFT(J$5,2))),""yyyy-MM-dd"")),0)),""""),selectedDate,DATE($P$3,MONTH(1&$N$3),VA"&"LUE(LEFT(J$5,2))),IF(logStatus<>"""",UPPER(logStatus),IF(selectedDate>TODAY(),""-"",IF(REGEXMATCH(J$5,""SUN""),""WO"",IF(J$8<>"""",IF(VALUE(J$8)>=9/24,""FD"",""HD""),""A"")))))))"),"A") -> A | K9: =IFERROR(__xludf.DUMMYFUNCTION("IF($A4="""","""",IF(K$5="""","""",LET(logStatus,IFNA(INDEX(DATA_LOG!$E:$E,MATCH(1,(DATA_LOG!$A:$A=$A4)*(TEXT(DATA_LOG!$B:$B,""yyyy-MM-dd"")=TEXT(DATE($P$3,MONTH(1&$N$3),VALUE(LEFT(K$5,2))),""yyyy-MM-dd"")),0)),""""),selectedDate,DATE($P$3,MONTH(1&$N$3),VA"&"LUE(LEFT(K$5,2))),IF(logStatus<>"""",UPPER(logStatus),IF(selectedDate>TODAY(),""-"",IF(REGEXMATCH(K$5,""SUN""),""WO"",IF(K$8<>"""",IF(VALUE(K$8)>=9/24,""FD"",""HD""),""A"")))))))"),"A") -> A | L9: =IFERROR(__xludf.DUMMYFUNCTION("IF($A4="""","""",IF(L$5="""","""",LET(logStatus,IFNA(INDEX(DATA_LOG!$E:$E,MATCH(1,(DATA_LOG!$A:$A=$A4)*(TEXT(DATA_LOG!$B:$B,""yyyy-MM-dd"")=TEXT(DATE($P$3,MONTH(1&$N$3),VALUE(LEFT(L$5,2))),""yyyy-MM-dd"")),0)),""""),selectedDate,DATE($P$3,MONTH(1&$N$3),VA"&"LUE(LEFT(L$5,2))),IF(logStatus<>"""",UPPER(logStatus),IF(selectedDate>TODAY(),""-"",IF(REGEXMATCH(L$5,""SUN""),""WO"",IF(L$8<>"""",IF(VALUE(L$8)>=9/24,""FD"",""HD""),""A"")))))))"),"A") -> A | M9: =IFERROR(__xludf.DUMMYFUNCTION("IF($A4="""","""",IF(M$5="""","""",LET(logStatus,IFNA(INDEX(DATA_LOG!$E:$E,MATCH(1,(DATA_LOG!$A:$A=$A4)*(TEXT(DATA_LOG!$B:$B,""yyyy-MM-dd"")=TEXT(DATE($P$3,MONTH(1&$N$3),VALUE(LEFT(M$5,2))),""yyyy-MM-dd"")),0)),""""),selectedDate,DATE($P$3,MONTH(1&$N$3),VA"&"LUE(LEFT(M$5,2))),IF(logStatus<>"""",UPPER(logStatus),IF(selectedDate>TODAY(),""-"",IF(REGEXMATCH(M$5,""SUN""),""WO"",IF(M$8<>"""",IF(VALUE(M$8)>=9/24,""FD"",""HD""),""A"")))))))"),"-") -> - | N9: =IFERROR(__xludf.DUMMYFUNCTION("IF($A4="""","""",IF(N$5="""","""",LET(logStatus,IFNA(INDEX(DATA_LOG!$E:$E,MATCH(1,(DATA_LOG!$A:$A=$A4)*(TEXT(DATA_LOG!$B:$B,""yyyy-MM-dd"")=TEXT(DATE($P$3,MONTH(1&$N$3),VALUE(LEFT(N$5,2))),""yyyy-MM-dd"")),0)),""""),selectedDate,DATE($P$3,MONTH(1&$N$3),VA"&"LUE(LEFT(N$5,2))),IF(logStatus<>"""",UPPER(logStatus),IF(selectedDate>TODAY(),""-"",IF(REGEXMATCH(N$5,""SUN""),""WO"",IF(N$8<>"""",IF(VALUE(N$8)>=9/24,""FD"",""HD""),""A"")))))))"),"-") -> - | O9: =IFERROR(__xludf.DUMMYFUNCTION("IF($A4="""","""",IF(O$5="""","""",LET(logStatus,IFNA(INDEX(DATA_LOG!$E:$E,MATCH(1,(DATA_LOG!$A:$A=$A4)*(TEXT(DATA_LOG!$B:$B,""yyyy-MM-dd"")=TEXT(DATE($P$3,MONTH(1&$N$3),VALUE(LEFT(O$5,2))),""yyyy-MM-dd"")),0)),""""),selectedDate,DATE($P$3,MONTH(1&$N$3),VA"&"LUE(LEFT(O$5,2))),IF(logStatus<>"""",UPPER(logStatus),IF(selectedDate>TODAY(),""-"",IF(REGEXMATCH(O$5,""SUN""),""WO"",IF(O$8<>"""",IF(VALUE(O$8)>=9/24,""FD"",""HD""),""A"")))))))"),"-") -> - | P9: =IFERROR(__xludf.DUMMYFUNCTION("IF($A4="""","""",IF(P$5="""","""",LET(logStatus,IFNA(INDEX(DATA_LOG!$E:$E,MATCH(1,(DATA_LOG!$A:$A=$A4)*(TEXT(DATA_LOG!$B:$B,""yyyy-MM-dd"")=TEXT(DATE($P$3,MONTH(1&$N$3),VALUE(LEFT(P$5,2))),""yyyy-MM-dd"")),0)),""""),selectedDate,DATE($P$3,MONTH(1&$N$3),VA"&"LUE(LEFT(P$5,2))),IF(logStatus<>"""",UPPER(logStatus),IF(selectedDate>TODAY(),""-"",IF(REGEXMATCH(P$5,""SUN""),""WO"",IF(P$8<>"""",IF(VALUE(P$8)>=9/24,""FD"",""HD""),""A"")))))))"),"-") -> - | Q9: =IFERROR(__xludf.DUMMYFUNCTION("IF($A4="""","""",IF(Q$5="""","""",LET(logStatus,IFNA(INDEX(DATA_LOG!$E:$E,MATCH(1,(DATA_LOG!$A:$A=$A4)*(TEXT(DATA_LOG!$B:$B,""yyyy-MM-dd"")=TEXT(DATE($P$3,MONTH(1&$N$3),VALUE(LEFT(Q$5,2))),""yyyy-MM-dd"")),0)),""""),selectedDate,DATE($P$3,MONTH(1&$N$3),VA"&"LUE(LEFT(Q$5,2))),IF(logStatus<>"""",UPPER(logStatus),IF(selectedDate>TODAY(),""-"",IF(REGEXMATCH(Q$5,""SUN""),""WO"",IF(Q$8<>"""",IF(VALUE(Q$8)>=9/24,""FD"",""HD""),""A"")))))))"),"-") -> - | R9: =IFERROR(__xludf.DUMMYFUNCTION("IF($A4="""","""",IF(R$5="""","""",LET(logStatus,IFNA(INDEX(DATA_LOG!$E:$E,MATCH(1,(DATA_LOG!$A:$A=$A4)*(TEXT(DATA_LOG!$B:$B,""yyyy-MM-dd"")=TEXT(DATE($P$3,MONTH(1&$N$3),VALUE(LEFT(R$5,2))),""yyyy-MM-dd"")),0)),""""),selectedDate,DATE($P$3,MONTH(1&$N$3),VA"&"LUE(LEFT(R$5,2))),IF(logStatus<>"""",UPPER(logStatus),IF(selectedDate>TODAY(),""-"",IF(REGEXMATCH(R$5,""SUN""),""WO"",IF(R$8<>"""",IF(VALUE(R$8)>=9/24,""FD"",""HD""),""A"")))))))"),"-") -> - | S9: =IFERROR(__xludf.DUMMYFUNCTION("IF($A4="""","""",IF(S$5="""","""",LET(logStatus,IFNA(INDEX(DATA_LOG!$E:$E,MATCH(1,(DATA_LOG!$A:$A=$A4)*(TEXT(DATA_LOG!$B:$B,""yyyy-MM-dd"")=TEXT(DATE($P$3,MONTH(1&$N$3),VALUE(LEFT(S$5,2))),""yyyy-MM-dd"")),0)),""""),selectedDate,DATE($P$3,MONTH(1&$N$3),VA"&"LUE(LEFT(S$5,2))),IF(logStatus<>"""",UPPER(logStatus),IF(selectedDate>TODAY(),""-"",IF(REGEXMATCH(S$5,""SUN""),""WO"",IF(S$8<>"""",IF(VALUE(S$8)>=9/24,""FD"",""HD""),""A"")))))))"),"-") -> - | T9: =IFERROR(__xludf.DUMMYFUNCTION("IF($A4="""","""",IF(T$5="""","""",LET(logStatus,IFNA(INDEX(DATA_LOG!$E:$E,MATCH(1,(DATA_LOG!$A:$A=$A4)*(TEXT(DATA_LOG!$B:$B,""yyyy-MM-dd"")=TEXT(DATE($P$3,MONTH(1&$N$3),VALUE(LEFT(T$5,2))),""yyyy-MM-dd"")),0)),""""),selectedDate,DATE($P$3,MONTH(1&$N$3),VA"&"LUE(LEFT(T$5,2))),IF(logStatus<>"""",UPPER(logStatus),IF(selectedDate>TODAY(),""-"",IF(REGEXMATCH(T$5,""SUN""),""WO"",IF(T$8<>"""",IF(VALUE(T$8)>=9/24,""FD"",""HD""),""A"")))))))"),"-") -> - | U9: =IFERROR(__xludf.DUMMYFUNCTION("IF($A4="""","""",IF(U$5="""","""",LET(logStatus,IFNA(INDEX(DATA_LOG!$E:$E,MATCH(1,(DATA_LOG!$A:$A=$A4)*(TEXT(DATA_LOG!$B:$B,""yyyy-MM-dd"")=TEXT(DATE($P$3,MONTH(1&$N$3),VALUE(LEFT(U$5,2))),""yyyy-MM-dd"")),0)),""""),selectedDate,DATE($P$3,MONTH(1&$N$3),VA"&"LUE(LEFT(U$5,2))),IF(logStatus<>"""",UPPER(logStatus),IF(selectedDate>TODAY(),""-"",IF(REGEXMATCH(U$5,""SUN""),""WO"",IF(U$8<>"""",IF(VALUE(U$8)>=9/24,""FD"",""HD""),""A"")))))))"),"-") -> - | V9: =IFERROR(__xludf.DUMMYFUNCTION("IF($A4="""","""",IF(V$5="""","""",LET(logStatus,IFNA(INDEX(DATA_LOG!$E:$E,MATCH(1,(DATA_LOG!$A:$A=$A4)*(TEXT(DATA_LOG!$B:$B,""yyyy-MM-dd"")=TEXT(DATE($P$3,MONTH(1&$N$3),VALUE(LEFT(V$5,2))),""yyyy-MM-dd"")),0)),""""),selectedDate,DATE($P$3,MONTH(1&$N$3),VA"&"LUE(LEFT(V$5,2))),IF(logStatus<>"""",UPPER(logStatus),IF(selectedDate>TODAY(),""-"",IF(REGEXMATCH(V$5,""SUN""),""WO"",IF(V$8<>"""",IF(VALUE(V$8)>=9/24,""FD"",""HD""),""A"")))))))"),"-") -> - | W9: =IFERROR(__xludf.DUMMYFUNCTION("IF($A4="""","""",IF(W$5="""","""",LET(logStatus,IFNA(INDEX(DATA_LOG!$E:$E,MATCH(1,(DATA_LOG!$A:$A=$A4)*(TEXT(DATA_LOG!$B:$B,""yyyy-MM-dd"")=TEXT(DATE($P$3,MONTH(1&$N$3),VALUE(LEFT(W$5,2))),""yyyy-MM-dd"")),0)),""""),selectedDate,DATE($P$3,MONTH(1&$N$3),VA"&"LUE(LEFT(W$5,2))),IF(logStatus<>"""",UPPER(logStatus),IF(selectedDate>TODAY(),""-"",IF(REGEXMATCH(W$5,""SUN""),""WO"",IF(W$8<>"""",IF(VALUE(W$8)>=9/24,""FD"",""HD""),""A"")))))))"),"-") -> - | X9: =IFERROR(__xludf.DUMMYFUNCTION("IF($A4="""","""",IF(X$5="""","""",LET(logStatus,IFNA(INDEX(DATA_LOG!$E:$E,MATCH(1,(DATA_LOG!$A:$A=$A4)*(TEXT(DATA_LOG!$B:$B,""yyyy-MM-dd"")=TEXT(DATE($P$3,MONTH(1&$N$3),VALUE(LEFT(X$5,2))),""yyyy-MM-dd"")),0)),""""),selectedDate,DATE($P$3,MONTH(1&$N$3),VA"&"LUE(LEFT(X$5,2))),IF(logStatus<>"""",UPPER(logStatus),IF(selectedDate>TODAY(),""-"",IF(REGEXMATCH(X$5,""SUN""),""WO"",IF(X$8<>"""",IF(VALUE(X$8)>=9/24,""FD"",""HD""),""A"")))))))"),"-") -> - | Y9: =IFERROR(__xludf.DUMMYFUNCTION("IF($A4="""","""",IF(Y$5="""","""",LET(logStatus,IFNA(INDEX(DATA_LOG!$E:$E,MATCH(1,(DATA_LOG!$A:$A=$A4)*(TEXT(DATA_LOG!$B:$B,""yyyy-MM-dd"")=TEXT(DATE($P$3,MONTH(1&$N$3),VALUE(LEFT(Y$5,2))),""yyyy-MM-dd"")),0)),""""),selectedDate,DATE($P$3,MONTH(1&$N$3),VA"&"LUE(LEFT(Y$5,2))),IF(logStatus<>"""",UPPER(logStatus),IF(selectedDate>TODAY(),""-"",IF(REGEXMATCH(Y$5,""SUN""),""WO"",IF(Y$8<>"""",IF(VALUE(Y$8)>=9/24,""FD"",""HD""),""A"")))))))"),"-") -> - | Z9: =IFERROR(__xludf.DUMMYFUNCTION("IF($A4="""","""",IF(Z$5="""","""",LET(logStatus,IFNA(INDEX(DATA_LOG!$E:$E,MATCH(1,(DATA_LOG!$A:$A=$A4)*(TEXT(DATA_LOG!$B:$B,""yyyy-MM-dd"")=TEXT(DATE($P$3,MONTH(1&$N$3),VALUE(LEFT(Z$5,2))),""yyyy-MM-dd"")),0)),""""),selectedDate,DATE($P$3,MONTH(1&$N$3),VA"&"LUE(LEFT(Z$5,2))),IF(logStatus<>"""",UPPER(logStatus),IF(selectedDate>TODAY(),""-"",IF(REGEXMATCH(Z$5,""SUN""),""WO"",IF(Z$8<>"""",IF(VALUE(Z$8)>=9/24,""FD"",""HD""),""A"")))))))"),"-") -> - | AA9: =IFERROR(__xludf.DUMMYFUNCTION("IF($A4="""","""",IF(AA$5="""","""",LET(logStatus,IFNA(INDEX(DATA_LOG!$E:$E,MATCH(1,(DATA_LOG!$A:$A=$A4)*(TEXT(DATA_LOG!$B:$B,""yyyy-MM-dd"")=TEXT(DATE($P$3,MONTH(1&$N$3),VALUE(LEFT(AA$5,2))),""yyyy-MM-dd"")),0)),""""),selectedDate,DATE($P$3,MONTH(1&$N$3),"&"VALUE(LEFT(AA$5,2))),IF(logStatus<>"""",UPPER(logStatus),IF(selectedDate>TODAY(),""-"",IF(REGEXMATCH(AA$5,""SUN""),""WO"",IF(AA$8<>"""",IF(VALUE(AA$8)>=9/24,""FD"",""HD""),""A"")))))))"),"-") -> - | AB9: =IFERROR(__xludf.DUMMYFUNCTION("IF($A4="""","""",IF(AB$5="""","""",LET(logStatus,IFNA(INDEX(DATA_LOG!$E:$E,MATCH(1,(DATA_LOG!$A:$A=$A4)*(TEXT(DATA_LOG!$B:$B,""yyyy-MM-dd"")=TEXT(DATE($P$3,MONTH(1&$N$3),VALUE(LEFT(AB$5,2))),""yyyy-MM-dd"")),0)),""""),selectedDate,DATE($P$3,MONTH(1&$N$3),"&"VALUE(LEFT(AB$5,2))),IF(logStatus<>"""",UPPER(logStatus),IF(selectedDate>TODAY(),""-"",IF(REGEXMATCH(AB$5,""SUN""),""WO"",IF(AB$8<>"""",IF(VALUE(AB$8)>=9/24,""FD"",""HD""),""A"")))))))"),"-") -> - | AC9: =IFERROR(__xludf.DUMMYFUNCTION("IF($A4="""","""",IF(AC$5="""","""",LET(logStatus,IFNA(INDEX(DATA_LOG!$E:$E,MATCH(1,(DATA_LOG!$A:$A=$A4)*(TEXT(DATA_LOG!$B:$B,""yyyy-MM-dd"")=TEXT(DATE($P$3,MONTH(1&$N$3),VALUE(LEFT(AC$5,2))),""yyyy-MM-dd"")),0)),""""),selectedDate,DATE($P$3,MONTH(1&$N$3),"&"VALUE(LEFT(AC$5,2))),IF(logStatus<>"""",UPPER(logStatus),IF(selectedDate>TODAY(),""-"",IF(REGEXMATCH(AC$5,""SUN""),""WO"",IF(AC$8<>"""",IF(VALUE(AC$8)>=9/24,""FD"",""HD""),""A"")))))))"),"-") -> - | AD9: =IFERROR(__xludf.DUMMYFUNCTION("IF($A4="""","""",IF(AD$5="""","""",LET(logStatus,IFNA(INDEX(DATA_LOG!$E:$E,MATCH(1,(DATA_LOG!$A:$A=$A4)*(TEXT(DATA_LOG!$B:$B,""yyyy-MM-dd"")=TEXT(DATE($P$3,MONTH(1&$N$3),VALUE(LEFT(AD$5,2))),""yyyy-MM-dd"")),0)),""""),selectedDate,DATE($P$3,MONTH(1&$N$3),"&"VALUE(LEFT(AD$5,2))),IF(logStatus<>"""",UPPER(logStatus),IF(selectedDate>TODAY(),""-"",IF(REGEXMATCH(AD$5,""SUN""),""WO"",IF(AD$8<>"""",IF(VALUE(AD$8)>=9/24,""FD"",""HD""),""A"")))))))"),"-") -> - | AE9: =IFERROR(__xludf.DUMMYFUNCTION("IF($A4="""","""",IF(AE$5="""","""",LET(logStatus,IFNA(INDEX(DATA_LOG!$E:$E,MATCH(1,(DATA_LOG!$A:$A=$A4)*(TEXT(DATA_LOG!$B:$B,""yyyy-MM-dd"")=TEXT(DATE($P$3,MONTH(1&$N$3),VALUE(LEFT(AE$5,2))),""yyyy-MM-dd"")),0)),""""),selectedDate,DATE($P$3,MONTH(1&$N$3),"&"VALUE(LEFT(AE$5,2))),IF(logStatus<>"""",UPPER(logStatus),IF(selectedDate>TODAY(),""-"",IF(REGEXMATCH(AE$5,""SUN""),""WO"",IF(AE$8<>"""",IF(VALUE(AE$8)>=9/24,""FD"",""HD""),""A"")))))))"),"-") -> - | AF9: =IFERROR(__xludf.DUMMYFUNCTION("IF($A4="""","""",IF(AF$5="""","""",LET(logStatus,IFNA(INDEX(DATA_LOG!$E:$E,MATCH(1,(DATA_LOG!$A:$A=$A4)*(TEXT(DATA_LOG!$B:$B,""yyyy-MM-dd"")=TEXT(DATE($P$3,MONTH(1&$N$3),VALUE(LEFT(AF$5,2))),""yyyy-MM-dd"")),0)),""""),selectedDate,DATE($P$3,MONTH(1&$N$3),"&"VALUE(LEFT(AF$5,2))),IF(logStatus<>"""",UPPER(logStatus),IF(selectedDate>TODAY(),""-"",IF(REGEXMATCH(AF$5,""SUN""),""WO"",IF(AF$8<>"""",IF(VALUE(AF$8)>=9/24,""FD"",""HD""),""A"")))))))"),"")
A11: {=INDEX(EMPLOYEE_LIST!$A:$A,INT((ROW()-4)/7)+2)} -> ARJUN BAHADUR | D11: =IF(A11="", "", IFERROR(VLOOKUP(A11, EMPLOYEE_LIST!$A:$H, 2, FALSE), "")) -> AYV-88 | H11: =IF(A11="", "", IFERROR(VLOOKUP(A11, EMPLOYEE_LIST!$A:$H, 3, FALSE), "")) -> SUPERVISOR | L11: =IF(A11="", "", IFERROR(VLOOKUP(A11, EMPLOYEE_LIST!$A:$H, 4, FALSE), "")) -> SUPERVISOR | P11: =IF($A11="", "", "Full Day: " & COUNTIF(B16:AF16, "FD")) -> Full Day: 0 | S11: =IF($A11="", "", "HALF Day: " & COUNTIF(B16:AF16, "HD")) -> HALF Day: 0 | V11: =IF($A11="", "", "ABSENT: " & COUNTIF(B16:AF16, "A")) -> ABSENT: 10 | Y11: =IF($A11="", "", "WEEK OFF: " & COUNTIF(B16:AF16, "WO")) -> WEEK OFF: 1 | AB11: =IF($A11="", "", "LEAVE: " & COUNTIF(B16:AF16, "L")) -> LEAVE: 0 | AD11: =IF($A11="", "", "HOLIDAY: " & COUNTIF(B16:AF16, "HL")) -> HOLIDAY: 0
A12: =IF($A11="", "", "DATE") -> DATE | B12: {=IF($A11="","",LET(mNum,MONTH(1&$N$3),start,DATE($P$3,mNum,1),days,DAY(EOMONTH(start,0)),MAP(SEQUENCE(1,days,0),LAMBDA(n,UPPER(TEXT(start+n,"dd (ddd)"))))))} -> 01 (TUE) | C12: 02 (WED) | D12: 03 (THU) | E12: 04 (FRI) | F12: 05 (SAT) | G12: 06 (SUN) | H12: 07 (MON) | I12: 08 (TUE) | J12: 09 (WED) | K12: 10 (THU) | L12: 11 (FRI) | M12: 12 (SAT) | N12: 13 (SUN) | O12: 14 (MON) | P12: 15 (TUE) | Q12: 16 (WED) | R12: 17 (THU) | S12: 18 (FRI) | T12: 19 (SAT) | U12: 20 (SUN) | V12: 21 (MON) | W12: 22 (TUE) | X12: 23 (WED) | Y12: 24 (THU) | Z12: 25 (FRI) | AA12: 26 (SAT) | AB12: 27 (SUN) | AC12: 28 (MON) | AD12: 29 (TUE) | AE12: 30 (WED)
A13: =IF($A11="", "", "IN") -> IN | B13: {=IF(OR($A11="",B$5=""),"",IFNA(INDEX(DATA_LOG!$C:$C,MATCH(1,(DATA_LOG!$A:$A=$A11)*(TEXT(DATA_LOG!$B:$B,"yyyy-MM-dd")=TEXT(DATE($P$3,MONTH(1&$N$3),VALUE(LEFT(B$5,2))),"yyyy-MM-dd")),0)),""))} | C13: {=IF(OR($A11="",C$5=""),"",IFNA(INDEX(DATA_LOG!$C:$C,MATCH(1,(DATA_LOG!$A:$A=$A11)*(TEXT(DATA_LOG!$B:$B,"yyyy-MM-dd")=TEXT(DATE($P$3,MONTH(1&$N$3),VALUE(LEFT(C$5,2))),"yyyy-MM-dd")),0)),""))} | D13: {=IF(OR($A11="",D$5=""),"",IFNA(INDEX(DATA_LOG!$C:$C,MATCH(1,(DATA_LOG!$A:$A=$A11)*(TEXT(DATA_LOG!$B:$B,"yyyy-MM-dd")=TEXT(DATE($P$3,MONTH(1&$N$3),VALUE(LEFT(D$5,2))),"yyyy-MM-dd")),0)),""))} | E13: {=IF(OR($A11="",E$5=""),"",IFNA(INDEX(DATA_LOG!$C:$C,MATCH(1,(DATA_LOG!$A:$A=$A11)*(TEXT(DATA_LOG!$B:$B,"yyyy-MM-dd")=TEXT(DATE($P$3,MONTH(1&$N$3),VALUE(LEFT(E$5,2))),"yyyy-MM-dd")),0)),""))} | F13: {=IF(OR($A11="",F$5=""),"",IFNA(INDEX(DATA_LOG!$C:$C,MATCH(1,(DATA_LOG!$A:$A=$A11)*(TEXT(DATA_LOG!$B:$B,"yyyy-MM-dd")=TEXT(DATE($P$3,MONTH(1&$N$3),VALUE(LEFT(F$5,2))),"yyyy-MM-dd")),0)),""))} | G13: {=IF(OR($A11="",G$5=""),"",IFNA(INDEX(DATA_LOG!$C:$C,MATCH(1,(DATA_LOG!$A:$A=$A11)*(TEXT(DATA_LOG!$B:$B,"yyyy-MM-dd")=TEXT(DATE($P$3,MONTH(1&$N$3),VALUE(LEFT(G$5,2))),"yyyy-MM-dd")),0)),""))} | H13: {=IF(OR($A11="",H$5=""),"",IFNA(INDEX(DATA_LOG!$C:$C,MATCH(1,(DATA_LOG!$A:$A=$A11)*(TEXT(DATA_LOG!$B:$B,"yyyy-MM-dd")=TEXT(DATE($P$3,MONTH(1&$N$3),VALUE(LEFT(H$5,2))),"yyyy-MM-dd")),0)),""))} | I13: {=IF(OR($A11="",I$5=""),"",IFNA(INDEX(DATA_LOG!$C:$C,MATCH(1,(DATA_LOG!$A:$A=$A11)*(TEXT(DATA_LOG!$B:$B,"yyyy-MM-dd")=TEXT(DATE($P$3,MONTH(1&$N$3),VALUE(LEFT(I$5,2))),"yyyy-MM-dd")),0)),""))} | ... AF13: {=IF(OR($A11="",AF$5=""),"",IFNA(INDEX(DATA_LOG!$C:$C,MATCH(1,(DATA_LOG!$A:$A=$A11)*(TEXT(DATA_LOG!$B:$B,"yyyy-MM-dd")=TEXT(DATE($P$3,MONTH(1&$N$3),VALUE(LEFT(AF$5,2))),"yyyy-MM-dd")),0)),""))}
A14: =IF($A11="", "", "OUT") -> OUT | B14: {=IF(OR($A11="",B$5=""),"",IFNA(INDEX(DATA_LOG!$D:$D,MATCH(1,(DATA_LOG!$A:$A=$A11)*(TEXT(DATA_LOG!$B:$B,"yyyy-MM-dd")=TEXT(DATE($P$3,MONTH(1&$N$3),VALUE(LEFT(B$5,2))),"yyyy-MM-dd")),0)),""))} | C14: {=IF(OR($A11="",C$5=""),"",IFNA(INDEX(DATA_LOG!$D:$D,MATCH(1,(DATA_LOG!$A:$A=$A11)*(TEXT(DATA_LOG!$B:$B,"yyyy-MM-dd")=TEXT(DATE($P$3,MONTH(1&$N$3),VALUE(LEFT(C$5,2))),"yyyy-MM-dd")),0)),""))} | D14: {=IF(OR($A11="",D$5=""),"",IFNA(INDEX(DATA_LOG!$D:$D,MATCH(1,(DATA_LOG!$A:$A=$A11)*(TEXT(DATA_LOG!$B:$B,"yyyy-MM-dd")=TEXT(DATE($P$3,MONTH(1&$N$3),VALUE(LEFT(D$5,2))),"yyyy-MM-dd")),0)),""))} | E14: {=IF(OR($A11="",E$5=""),"",IFNA(INDEX(DATA_LOG!$D:$D,MATCH(1,(DATA_LOG!$A:$A=$A11)*(TEXT(DATA_LOG!$B:$B,"yyyy-MM-dd")=TEXT(DATE($P$3,MONTH(1&$N$3),VALUE(LEFT(E$5,2))),"yyyy-MM-dd")),0)),""))} | F14: {=IF(OR($A11="",F$5=""),"",IFNA(INDEX(DATA_LOG!$D:$D,MATCH(1,(DATA_LOG!$A:$A=$A11)*(TEXT(DATA_LOG!$B:$B,"yyyy-MM-dd")=TEXT(DATE($P$3,MONTH(1&$N$3),VALUE(LEFT(F$5,2))),"yyyy-MM-dd")),0)),""))} | G14: {=IF(OR($A11="",G$5=""),"",IFNA(INDEX(DATA_LOG!$D:$D,MATCH(1,(DATA_LOG!$A:$A=$A11)*(TEXT(DATA_LOG!$B:$B,"yyyy-MM-dd")=TEXT(DATE($P$3,MONTH(1&$N$3),VALUE(LEFT(G$5,2))),"yyyy-MM-dd")),0)),""))} | H14: {=IF(OR($A11="",H$5=""),"",IFNA(INDEX(DATA_LOG!$D:$D,MATCH(1,(DATA_LOG!$A:$A=$A11)*(TEXT(DATA_LOG!$B:$B,"yyyy-MM-dd")=TEXT(DATE($P$3,MONTH(1&$N$3),VALUE(LEFT(H$5,2))),"yyyy-MM-dd")),0)),""))} | I14: {=IF(OR($A11="",I$5=""),"",IFNA(INDEX(DATA_LOG!$D:$D,MATCH(1,(DATA_LOG!$A:$A=$A11)*(TEXT(DATA_LOG!$B:$B,"yyyy-MM-dd")=TEXT(DATE($P$3,MONTH(1&$N$3),VALUE(LEFT(I$5,2))),"yyyy-MM-dd")),0)),""))} | ... AF14: {=IF(OR($A11="",AF$5=""),"",IFNA(INDEX(DATA_LOG!$D:$D,MATCH(1,(DATA_LOG!$A:$A=$A11)*(TEXT(DATA_LOG!$B:$B,"yyyy-MM-dd")=TEXT(DATE($P$3,MONTH(1&$N$3),VALUE(LEFT(AF$5,2))),"yyyy-MM-dd")),0)),""))}
A15: =IF($A11="", "", "TOTAL") -> TOTAL | B15: =IF(OR(B13="",B14=""),"",B14-B13) | C15: =IF(OR(C13="",C14=""),"",C14-C13) | D15: =IF(OR(D13="",D14=""),"",D14-D13) | E15: =IF(OR(E13="",E14=""),"",E14-E13) | F15: =IF(OR(F13="",F14=""),"",F14-F13) | G15: =IF(OR(G13="",G14=""),"",G14-G13) | H15: =IF(OR(H13="",H14=""),"",H14-H13) | I15: =IF(OR(I13="",I14=""),"",I14-I13) | ... AF15: =IF(OR(AF13="",AF14=""),"",AF14-AF13)
A16: =IF($A11="", "", "STATUS") -> STATUS | B16: =IFERROR(__xludf.DUMMYFUNCTION("IF($A11="""","""",IF(B$12="""","""",LET(logStatus,IFNA(INDEX(DATA_LOG!$E:$E,MATCH(1,(DATA_LOG!$A:$A=$A11)*(TEXT(DATA_LOG!$B:$B,""yyyy-MM-dd"")=TEXT(DATE($P$3,MONTH(1&$N$3),VALUE(LEFT(B$12,2))),""yyyy-MM-dd"")),0)),""""),selectedDate,DATE($P$3,MONTH(1&$N$3"&"),VALUE(LEFT(B$12,2))),IF(logStatus<>"""",UPPER(logStatus),IF(selectedDate>TODAY(),""-"",IF(REGEXMATCH(B$12,""SUN""),""WO"",IF(B$15<>"""",IF(VALUE(B$15)>=9/24,""FD"",""HD""),""A"")))))))"),"A") -> A | C16: =IFERROR(__xludf.DUMMYFUNCTION("IF($A11="""","""",IF(C$12="""","""",LET(logStatus,IFNA(INDEX(DATA_LOG!$E:$E,MATCH(1,(DATA_LOG!$A:$A=$A11)*(TEXT(DATA_LOG!$B:$B,""yyyy-MM-dd"")=TEXT(DATE($P$3,MONTH(1&$N$3),VALUE(LEFT(C$12,2))),""yyyy-MM-dd"")),0)),""""),selectedDate,DATE($P$3,MONTH(1&$N$3"&"),VALUE(LEFT(C$12,2))),IF(logStatus<>"""",UPPER(logStatus),IF(selectedDate>TODAY(),""-"",IF(REGEXMATCH(C$12,""SUN""),""WO"",IF(C$15<>"""",IF(VALUE(C$15)>=9/24,""FD"",""HD""),""A"")))))))"),"A") -> A | D16: =IFERROR(__xludf.DUMMYFUNCTION("IF($A11="""","""",IF(D$12="""","""",LET(logStatus,IFNA(INDEX(DATA_LOG!$E:$E,MATCH(1,(DATA_LOG!$A:$A=$A11)*(TEXT(DATA_LOG!$B:$B,""yyyy-MM-dd"")=TEXT(DATE($P$3,MONTH(1&$N$3),VALUE(LEFT(D$12,2))),""yyyy-MM-dd"")),0)),""""),selectedDate,DATE($P$3,MONTH(1&$N$3"&"),VALUE(LEFT(D$12,2))),IF(logStatus<>"""",UPPER(logStatus),IF(selectedDate>TODAY(),""-"",IF(REGEXMATCH(D$12,""SUN""),""WO"",IF(D$15<>"""",IF(VALUE(D$15)>=9/24,""FD"",""HD""),""A"")))))))"),"A") -> A | E16: =IFERROR(__xludf.DUMMYFUNCTION("IF($A11="""","""",IF(E$12="""","""",LET(logStatus,IFNA(INDEX(DATA_LOG!$E:$E,MATCH(1,(DATA_LOG!$A:$A=$A11)*(TEXT(DATA_LOG!$B:$B,""yyyy-MM-dd"")=TEXT(DATE($P$3,MONTH(1&$N$3),VALUE(LEFT(E$12,2))),""yyyy-MM-dd"")),0)),""""),selectedDate,DATE($P$3,MONTH(1&$N$3"&"),VALUE(LEFT(E$12,2))),IF(logStatus<>"""",UPPER(logStatus),IF(selectedDate>TODAY(),""-"",IF(REGEXMATCH(E$12,""SUN""),""WO"",IF(E$15<>"""",IF(VALUE(E$15)>=9/24,""FD"",""HD""),""A"")))))))"),"A") -> A | F16: =IFERROR(__xludf.DUMMYFUNCTION("IF($A11="""","""",IF(F$12="""","""",LET(logStatus,IFNA(INDEX(DATA_LOG!$E:$E,MATCH(1,(DATA_LOG!$A:$A=$A11)*(TEXT(DATA_LOG!$B:$B,""yyyy-MM-dd"")=TEXT(DATE($P$3,MONTH(1&$N$3),VALUE(LEFT(F$12,2))),""yyyy-MM-dd"")),0)),""""),selectedDate,DATE($P$3,MONTH(1&$N$3"&"),VALUE(LEFT(F$12,2))),IF(logStatus<>"""",UPPER(logStatus),IF(selectedDate>TODAY(),""-"",IF(REGEXMATCH(F$12,""SUN""),""WO"",IF(F$15<>"""",IF(VALUE(F$15)>=9/24,""FD"",""HD""),""A"")))))))"),"A") -> A | G16: =IFERROR(__xludf.DUMMYFUNCTION("IF($A11="""","""",IF(G$12="""","""",LET(logStatus,IFNA(INDEX(DATA_LOG!$E:$E,MATCH(1,(DATA_LOG!$A:$A=$A11)*(TEXT(DATA_LOG!$B:$B,""yyyy-MM-dd"")=TEXT(DATE($P$3,MONTH(1&$N$3),VALUE(LEFT(G$12,2))),""yyyy-MM-dd"")),0)),""""),selectedDate,DATE($P$3,MONTH(1&$N$3"&"),VALUE(LEFT(G$12,2))),IF(logStatus<>"""",UPPER(logStatus),IF(selectedDate>TODAY(),""-"",IF(REGEXMATCH(G$12,""SUN""),""WO"",IF(G$15<>"""",IF(VALUE(G$15)>=9/24,""FD"",""HD""),""A"")))))))"),"WO") -> WO | H16: =IFERROR(__xludf.DUMMYFUNCTION("IF($A11="""","""",IF(H$12="""","""",LET(logStatus,IFNA(INDEX(DATA_LOG!$E:$E,MATCH(1,(DATA_LOG!$A:$A=$A11)*(TEXT(DATA_LOG!$B:$B,""yyyy-MM-dd"")=TEXT(DATE($P$3,MONTH(1&$N$3),VALUE(LEFT(H$12,2))),""yyyy-MM-dd"")),0)),""""),selectedDate,DATE($P$3,MONTH(1&$N$3"&"),VALUE(LEFT(H$12,2))),IF(logStatus<>"""",UPPER(logStatus),IF(selectedDate>TODAY(),""-"",IF(REGEXMATCH(H$12,""SUN""),""WO"",IF(H$15<>"""",IF(VALUE(H$15)>=9/24,""FD"",""HD""),""A"")))))))"),"A") -> A | I16: =IFERROR(__xludf.DUMMYFUNCTION("IF($A11="""","""",IF(I$12="""","""",LET(logStatus,IFNA(INDEX(DATA_LOG!$E:$E,MATCH(1,(DATA_LOG!$A:$A=$A11)*(TEXT(DATA_LOG!$B:$B,""yyyy-MM-dd"")=TEXT(DATE($P$3,MONTH(1&$N$3),VALUE(LEFT(I$12,2))),""yyyy-MM-dd"")),0)),""""),selectedDate,DATE($P$3,MONTH(1&$N$3"&"),VALUE(LEFT(I$12,2))),IF(logStatus<>"""",UPPER(logStatus),IF(selectedDate>TODAY(),""-"",IF(REGEXMATCH(I$12,""SUN""),""WO"",IF(I$15<>"""",IF(VALUE(I$15)>=9/24,""FD"",""HD""),""A"")))))))"),"A") -> A | J16: =IFERROR(__xludf.DUMMYFUNCTION("IF($A11="""","""",IF(J$12="""","""",LET(logStatus,IFNA(INDEX(DATA_LOG!$E:$E,MATCH(1,(DATA_LOG!$A:$A=$A11)*(TEXT(DATA_LOG!$B:$B,""yyyy-MM-dd"")=TEXT(DATE($P$3,MONTH(1&$N$3),VALUE(LEFT(J$12,2))),""yyyy-MM-dd"")),0)),""""),selectedDate,DATE($P$3,MONTH(1&$N$3"&"),VALUE(LEFT(J$12,2))),IF(logStatus<>"""",UPPER(logStatus),IF(selectedDate>TODAY(),""-"",IF(REGEXMATCH(J$12,""SUN""),""WO"",IF(J$15<>"""",IF(VALUE(J$15)>=9/24,""FD"",""HD""),""A"")))))))"),"A") -> A | K16: =IFERROR(__xludf.DUMMYFUNCTION("IF($A11="""","""",IF(K$12="""","""",LET(logStatus,IFNA(INDEX(DATA_LOG!$E:$E,MATCH(1,(DATA_LOG!$A:$A=$A11)*(TEXT(DATA_LOG!$B:$B,""yyyy-MM-dd"")=TEXT(DATE($P$3,MONTH(1&$N$3),VALUE(LEFT(K$12,2))),""yyyy-MM-dd"")),0)),""""),selectedDate,DATE($P$3,MONTH(1&$N$3"&"),VALUE(LEFT(K$12,2))),IF(logStatus<>"""",UPPER(logStatus),IF(selectedDate>TODAY(),""-"",IF(REGEXMATCH(K$12,""SUN""),""WO"",IF(K$15<>"""",IF(VALUE(K$15)>=9/24,""FD"",""HD""),""A"")))))))"),"A") -> A | L16: =IFERROR(__xludf.DUMMYFUNCTION("IF($A11="""","""",IF(L$12="""","""",LET(logStatus,IFNA(INDEX(DATA_LOG!$E:$E,MATCH(1,(DATA_LOG!$A:$A=$A11)*(TEXT(DATA_LOG!$B:$B,""yyyy-MM-dd"")=TEXT(DATE($P$3,MONTH(1&$N$3),VALUE(LEFT(L$12,2))),""yyyy-MM-dd"")),0)),""""),selectedDate,DATE($P$3,MONTH(1&$N$3"&"),VALUE(LEFT(L$12,2))),IF(logStatus<>"""",UPPER(logStatus),IF(selectedDate>TODAY(),""-"",IF(REGEXMATCH(L$12,""SUN""),""WO"",IF(L$15<>"""",IF(VALUE(L$15)>=9/24,""FD"",""HD""),""A"")))))))"),"A") -> A | M16: =IFERROR(__xludf.DUMMYFUNCTION("IF($A11="""","""",IF(M$12="""","""",LET(logStatus,IFNA(INDEX(DATA_LOG!$E:$E,MATCH(1,(DATA_LOG!$A:$A=$A11)*(TEXT(DATA_LOG!$B:$B,""yyyy-MM-dd"")=TEXT(DATE($P$3,MONTH(1&$N$3),VALUE(LEFT(M$12,2))),""yyyy-MM-dd"")),0)),""""),selectedDate,DATE($P$3,MONTH(1&$N$3"&"),VALUE(LEFT(M$12,2))),IF(logStatus<>"""",UPPER(logStatus),IF(selectedDate>TODAY(),""-"",IF(REGEXMATCH(M$12,""SUN""),""WO"",IF(M$15<>"""",IF(VALUE(M$15)>=9/24,""FD"",""HD""),""A"")))))))"),"-") -> - | N16: =IFERROR(__xludf.DUMMYFUNCTION("IF($A11="""","""",IF(N$12="""","""",LET(logStatus,IFNA(INDEX(DATA_LOG!$E:$E,MATCH(1,(DATA_LOG!$A:$A=$A11)*(TEXT(DATA_LOG!$B:$B,""yyyy-MM-dd"")=TEXT(DATE($P$3,MONTH(1&$N$3),VALUE(LEFT(N$12,2))),""yyyy-MM-dd"")),0)),""""),selectedDate,DATE($P$3,MONTH(1&$N$3"&"),VALUE(LEFT(N$12,2))),IF(logStatus<>"""",UPPER(logStatus),IF(selectedDate>TODAY(),""-"",IF(REGEXMATCH(N$12,""SUN""),""WO"",IF(N$15<>"""",IF(VALUE(N$15)>=9/24,""FD"",""HD""),""A"")))))))"),"-") -> - | O16: =IFERROR(__xludf.DUMMYFUNCTION("IF($A11="""","""",IF(O$12="""","""",LET(logStatus,IFNA(INDEX(DATA_LOG!$E:$E,MATCH(1,(DATA_LOG!$A:$A=$A11)*(TEXT(DATA_LOG!$B:$B,""yyyy-MM-dd"")=TEXT(DATE($P$3,MONTH(1&$N$3),VALUE(LEFT(O$12,2))),""yyyy-MM-dd"")),0)),""""),selectedDate,DATE($P$3,MONTH(1&$N$3"&"),VALUE(LEFT(O$12,2))),IF(logStatus<>"""",UPPER(logStatus),IF(selectedDate>TODAY(),""-"",IF(REGEXMATCH(O$12,""SUN""),""WO"",IF(O$15<>"""",IF(VALUE(O$15)>=9/24,""FD"",""HD""),""A"")))))))"),"-") -> - | P16: =IFERROR(__xludf.DUMMYFUNCTION("IF($A11="""","""",IF(P$12="""","""",LET(logStatus,IFNA(INDEX(DATA_LOG!$E:$E,MATCH(1,(DATA_LOG!$A:$A=$A11)*(TEXT(DATA_LOG!$B:$B,""yyyy-MM-dd"")=TEXT(DATE($P$3,MONTH(1&$N$3),VALUE(LEFT(P$12,2))),""yyyy-MM-dd"")),0)),""""),selectedDate,DATE($P$3,MONTH(1&$N$3"&"),VALUE(LEFT(P$12,2))),IF(logStatus<>"""",UPPER(logStatus),IF(selectedDate>TODAY(),""-"",IF(REGEXMATCH(P$12,""SUN""),""WO"",IF(P$15<>"""",IF(VALUE(P$15)>=9/24,""FD"",""HD""),""A"")))))))"),"-") -> - | Q16: =IFERROR(__xludf.DUMMYFUNCTION("IF($A11="""","""",IF(Q$12="""","""",LET(logStatus,IFNA(INDEX(DATA_LOG!$E:$E,MATCH(1,(DATA_LOG!$A:$A=$A11)*(TEXT(DATA_LOG!$B:$B,""yyyy-MM-dd"")=TEXT(DATE($P$3,MONTH(1&$N$3),VALUE(LEFT(Q$12,2))),""yyyy-MM-dd"")),0)),""""),selectedDate,DATE($P$3,MONTH(1&$N$3"&"),VALUE(LEFT(Q$12,2))),IF(logStatus<>"""",UPPER(logStatus),IF(selectedDate>TODAY(),""-"",IF(REGEXMATCH(Q$12,""SUN""),""WO"",IF(Q$15<>"""",IF(VALUE(Q$15)>=9/24,""FD"",""HD""),""A"")))))))"),"-") -> - | R16: =IFERROR(__xludf.DUMMYFUNCTION("IF($A11="""","""",IF(R$12="""","""",LET(logStatus,IFNA(INDEX(DATA_LOG!$E:$E,MATCH(1,(DATA_LOG!$A:$A=$A11)*(TEXT(DATA_LOG!$B:$B,""yyyy-MM-dd"")=TEXT(DATE($P$3,MONTH(1&$N$3),VALUE(LEFT(R$12,2))),""yyyy-MM-dd"")),0)),""""),selectedDate,DATE($P$3,MONTH(1&$N$3"&"),VALUE(LEFT(R$12,2))),IF(logStatus<>"""",UPPER(logStatus),IF(selectedDate>TODAY(),""-"",IF(REGEXMATCH(R$12,""SUN""),""WO"",IF(R$15<>"""",IF(VALUE(R$15)>=9/24,""FD"",""HD""),""A"")))))))"),"-") -> - | S16: =IFERROR(__xludf.DUMMYFUNCTION("IF($A11="""","""",IF(S$12="""","""",LET(logStatus,IFNA(INDEX(DATA_LOG!$E:$E,MATCH(1,(DATA_LOG!$A:$A=$A11)*(TEXT(DATA_LOG!$B:$B,""yyyy-MM-dd"")=TEXT(DATE($P$3,MONTH(1&$N$3),VALUE(LEFT(S$12,2))),""yyyy-MM-dd"")),0)),""""),selectedDate,DATE($P$3,MONTH(1&$N$3"&"),VALUE(LEFT(S$12,2))),IF(logStatus<>"""",UPPER(logStatus),IF(selectedDate>TODAY(),""-"",IF(REGEXMATCH(S$12,""SUN""),""WO"",IF(S$15<>"""",IF(VALUE(S$15)>=9/24,""FD"",""HD""),""A"")))))))"),"-") -> - | T16: =IFERROR(__xludf.DUMMYFUNCTION("IF($A11="""","""",IF(T$12="""","""",LET(logStatus,IFNA(INDEX(DATA_LOG!$E:$E,MATCH(1,(DATA_LOG!$A:$A=$A11)*(TEXT(DATA_LOG!$B:$B,""yyyy-MM-dd"")=TEXT(DATE($P$3,MONTH(1&$N$3),VALUE(LEFT(T$12,2))),""yyyy-MM-dd"")),0)),""""),selectedDate,DATE($P$3,MONTH(1&$N$3"&"),VALUE(LEFT(T$12,2))),IF(logStatus<>"""",UPPER(logStatus),IF(selectedDate>TODAY(),""-"",IF(REGEXMATCH(T$12,""SUN""),""WO"",IF(T$15<>"""",IF(VALUE(T$15)>=9/24,""FD"",""HD""),""A"")))))))"),"-") -> - | U16: =IFERROR(__xludf.DUMMYFUNCTION("IF($A11="""","""",IF(U$12="""","""",LET(logStatus,IFNA(INDEX(DATA_LOG!$E:$E,MATCH(1,(DATA_LOG!$A:$A=$A11)*(TEXT(DATA_LOG!$B:$B,""yyyy-MM-dd"")=TEXT(DATE($P$3,MONTH(1&$N$3),VALUE(LEFT(U$12,2))),""yyyy-MM-dd"")),0)),""""),selectedDate,DATE($P$3,MONTH(1&$N$3"&"),VALUE(LEFT(U$12,2))),IF(logStatus<>"""",UPPER(logStatus),IF(selectedDate>TODAY(),""-"",IF(REGEXMATCH(U$12,""SUN""),""WO"",IF(U$15<>"""",IF(VALUE(U$15)>=9/24,""FD"",""HD""),""A"")))))))"),"-") -> - | V16: =IFERROR(__xludf.DUMMYFUNCTION("IF($A11="""","""",IF(V$12="""","""",LET(logStatus,IFNA(INDEX(DATA_LOG!$E:$E,MATCH(1,(DATA_LOG!$A:$A=$A11)*(TEXT(DATA_LOG!$B:$B,""yyyy-MM-dd"")=TEXT(DATE($P$3,MONTH(1&$N$3),VALUE(LEFT(V$12,2))),""yyyy-MM-dd"")),0)),""""),selectedDate,DATE($P$3,MONTH(1&$N$3"&"),VALUE(LEFT(V$12,2))),IF(logStatus<>"""",UPPER(logStatus),IF(selectedDate>TODAY(),""-"",IF(REGEXMATCH(V$12,""SUN""),""WO"",IF(V$15<>"""",IF(VALUE(V$15)>=9/24,""FD"",""HD""),""A"")))))))"),"-") -> - | W16: =IFERROR(__xludf.DUMMYFUNCTION("IF($A11="""","""",IF(W$12="""","""",LET(logStatus,IFNA(INDEX(DATA_LOG!$E:$E,MATCH(1,(DATA_LOG!$A:$A=$A11)*(TEXT(DATA_LOG!$B:$B,""yyyy-MM-dd"")=TEXT(DATE($P$3,MONTH(1&$N$3),VALUE(LEFT(W$12,2))),""yyyy-MM-dd"")),0)),""""),selectedDate,DATE($P$3,MONTH(1&$N$3"&"),VALUE(LEFT(W$12,2))),IF(logStatus<>"""",UPPER(logStatus),IF(selectedDate>TODAY(),""-"",IF(REGEXMATCH(W$12,""SUN""),""WO"",IF(W$15<>"""",IF(VALUE(W$15)>=9/24,""FD"",""HD""),""A"")))))))"),"-") -> - | X16: =IFERROR(__xludf.DUMMYFUNCTION("IF($A11="""","""",IF(X$12="""","""",LET(logStatus,IFNA(INDEX(DATA_LOG!$E:$E,MATCH(1,(DATA_LOG!$A:$A=$A11)*(TEXT(DATA_LOG!$B:$B,""yyyy-MM-dd"")=TEXT(DATE($P$3,MONTH(1&$N$3),VALUE(LEFT(X$12,2))),""yyyy-MM-dd"")),0)),""""),selectedDate,DATE($P$3,MONTH(1&$N$3"&"),VALUE(LEFT(X$12,2))),IF(logStatus<>"""",UPPER(logStatus),IF(selectedDate>TODAY(),""-"",IF(REGEXMATCH(X$12,""SUN""),""WO"",IF(X$15<>"""",IF(VALUE(X$15)>=9/24,""FD"",""HD""),""A"")))))))"),"-") -> - | Y16: =IFERROR(__xludf.DUMMYFUNCTION("IF($A11="""","""",IF(Y$12="""","""",LET(logStatus,IFNA(INDEX(DATA_LOG!$E:$E,MATCH(1,(DATA_LOG!$A:$A=$A11)*(TEXT(DATA_LOG!$B:$B,""yyyy-MM-dd"")=TEXT(DATE($P$3,MONTH(1&$N$3),VALUE(LEFT(Y$12,2))),""yyyy-MM-dd"")),0)),""""),selectedDate,DATE($P$3,MONTH(1&$N$3"&"),VALUE(LEFT(Y$12,2))),IF(logStatus<>"""",UPPER(logStatus),IF(selectedDate>TODAY(),""-"",IF(REGEXMATCH(Y$12,""SUN""),""WO"",IF(Y$15<>"""",IF(VALUE(Y$15)>=9/24,""FD"",""HD""),""A"")))))))"),"-") -> - | Z16: =IFERROR(__xludf.DUMMYFUNCTION("IF($A11="""","""",IF(Z$12="""","""",LET(logStatus,IFNA(INDEX(DATA_LOG!$E:$E,MATCH(1,(DATA_LOG!$A:$A=$A11)*(TEXT(DATA_LOG!$B:$B,""yyyy-MM-dd"")=TEXT(DATE($P$3,MONTH(1&$N$3),VALUE(LEFT(Z$12,2))),""yyyy-MM-dd"")),0)),""""),selectedDate,DATE($P$3,MONTH(1&$N$3"&"),VALUE(LEFT(Z$12,2))),IF(logStatus<>"""",UPPER(logStatus),IF(selectedDate>TODAY(),""-"",IF(REGEXMATCH(Z$12,""SUN""),""WO"",IF(Z$15<>"""",IF(VALUE(Z$15)>=9/24,""FD"",""HD""),""A"")))))))"),"-") -> - | AA16: =IFERROR(__xludf.DUMMYFUNCTION("IF($A11="""","""",IF(AA$12="""","""",LET(logStatus,IFNA(INDEX(DATA_LOG!$E:$E,MATCH(1,(DATA_LOG!$A:$A=$A11)*(TEXT(DATA_LOG!$B:$B,""yyyy-MM-dd"")=TEXT(DATE($P$3,MONTH(1&$N$3),VALUE(LEFT(AA$12,2))),""yyyy-MM-dd"")),0)),""""),selectedDate,DATE($P$3,MONTH(1&$N"&"$3),VALUE(LEFT(AA$12,2))),IF(logStatus<>"""",UPPER(logStatus),IF(selectedDate>TODAY(),""-"",IF(REGEXMATCH(AA$12,""SUN""),""WO"",IF(AA$15<>"""",IF(VALUE(AA$15)>=9/24,""FD"",""HD""),""A"")))))))"),"-") -> - | AB16: =IFERROR(__xludf.DUMMYFUNCTION("IF($A11="""","""",IF(AB$12="""","""",LET(logStatus,IFNA(INDEX(DATA_LOG!$E:$E,MATCH(1,(DATA_LOG!$A:$A=$A11)*(TEXT(DATA_LOG!$B:$B,""yyyy-MM-dd"")=TEXT(DATE($P$3,MONTH(1&$N$3),VALUE(LEFT(AB$12,2))),""yyyy-MM-dd"")),0)),""""),selectedDate,DATE($P$3,MONTH(1&$N"&"$3),VALUE(LEFT(AB$12,2))),IF(logStatus<>"""",UPPER(logStatus),IF(selectedDate>TODAY(),""-"",IF(REGEXMATCH(AB$12,""SUN""),""WO"",IF(AB$15<>"""",IF(VALUE(AB$15)>=9/24,""FD"",""HD""),""A"")))))))"),"-") -> - | AC16: =IFERROR(__xludf.DUMMYFUNCTION("IF($A11="""","""",IF(AC$12="""","""",LET(logStatus,IFNA(INDEX(DATA_LOG!$E:$E,MATCH(1,(DATA_LOG!$A:$A=$A11)*(TEXT(DATA_LOG!$B:$B,""yyyy-MM-dd"")=TEXT(DATE($P$3,MONTH(1&$N$3),VALUE(LEFT(AC$12,2))),""yyyy-MM-dd"")),0)),""""),selectedDate,DATE($P$3,MONTH(1&$N"&"$3),VALUE(LEFT(AC$12,2))),IF(logStatus<>"""",UPPER(logStatus),IF(selectedDate>TODAY(),""-"",IF(REGEXMATCH(AC$12,""SUN""),""WO"",IF(AC$15<>"""",IF(VALUE(AC$15)>=9/24,""FD"",""HD""),""A"")))))))"),"-") -> - | AD16: =IFERROR(__xludf.DUMMYFUNCTION("IF($A11="""","""",IF(AD$12="""","""",LET(logStatus,IFNA(INDEX(DATA_LOG!$E:$E,MATCH(1,(DATA_LOG!$A:$A=$A11)*(TEXT(DATA_LOG!$B:$B,""yyyy-MM-dd"")=TEXT(DATE($P$3,MONTH(1&$N$3),VALUE(LEFT(AD$12,2))),""yyyy-MM-dd"")),0)),""""),selectedDate,DATE($P$3,MONTH(1&$N"&"$3),VALUE(LEFT(AD$12,2))),IF(logStatus<>"""",UPPER(logStatus),IF(selectedDate>TODAY(),""-"",IF(REGEXMATCH(AD$12,""SUN""),""WO"",IF(AD$15<>"""",IF(VALUE(AD$15)>=9/24,""FD"",""HD""),""A"")))))))"),"-") -> - | AE16: =IFERROR(__xludf.DUMMYFUNCTION("IF($A11="""","""",IF(AE$12="""","""",LET(logStatus,IFNA(INDEX(DATA_LOG!$E:$E,MATCH(1,(DATA_LOG!$A:$A=$A11)*(TEXT(DATA_LOG!$B:$B,""yyyy-MM-dd"")=TEXT(DATE($P$3,MONTH(1&$N$3),VALUE(LEFT(AE$12,2))),""yyyy-MM-dd"")),0)),""""),selectedDate,DATE($P$3,MONTH(1&$N"&"$3),VALUE(LEFT(AE$12,2))),IF(logStatus<>"""",UPPER(logStatus),IF(selectedDate>TODAY(),""-"",IF(REGEXMATCH(AE$12,""SUN""),""WO"",IF(AE$15<>"""",IF(VALUE(AE$15)>=9/24,""FD"",""HD""),""A"")))))))"),"-") -> - | AF16: =IFERROR(__xludf.DUMMYFUNCTION("IF($A11="""","""",IF(AF$12="""","""",LET(logStatus,IFNA(INDEX(DATA_LOG!$E:$E,MATCH(1,(DATA_LOG!$A:$A=$A11)*(TEXT(DATA_LOG!$B:$B,""yyyy-MM-dd"")=TEXT(DATE($P$3,MONTH(1&$N$3),VALUE(LEFT(AF$12,2))),""yyyy-MM-dd"")),0)),""""),selectedDate,DATE($P$3,MONTH(1&$N"&"$3),VALUE(LEFT(AF$12,2))),IF(logStatus<>"""",UPPER(logStatus),IF(selectedDate>TODAY(),""-"",IF(REGEXMATCH(AF$12,""SUN""),""WO"",IF(AF$15<>"""",IF(VALUE(AF$15)>=9/24,""FD"",""HD""),""A"")))))))"),"")
A18: {=INDEX(EMPLOYEE_LIST!$A:$A,INT((ROW()-4)/7)+2)} -> ARYAN CHANDRAKAR | D18: =IF(A18="", "", IFERROR(VLOOKUP(A18, EMPLOYEE_LIST!$A:$H, 2, FALSE), "")) -> AYV-71 | H18: =IF(A18="", "", IFERROR(VLOOKUP(A18, EMPLOYEE_LIST!$A:$H, 3, FALSE), "")) -> ENGINEERING | L18: =IF(A18="", "", IFERROR(VLOOKUP(A18, EMPLOYEE_LIST!$A:$H, 4, FALSE), "")) -> SITE ENGINEER | P18: =IF($A18="", "", "Full Day: " & COUNTIF(B23:AF23, "FD")) -> Full Day: 0 | S18: =IF($A18="", "", "HALF Day: " & COUNTIF(B23:AF23, "HD")) -> HALF Day: 0 | V18: =IF($A18="", "", "ABSENT: " & COUNTIF(B23:AF23, "A")) -> ABSENT: 10 | Y18: =IF($A18="", "", "WEEK OFF: " & COUNTIF(B23:AF23, "WO")) -> WEEK OFF: 1 | AB18: =IF($A18="", "", "LEAVE: " & COUNTIF(B23:AF23, "L")) -> LEAVE: 0 | AD18: =IF($A18="", "", "HOLIDAY: " & COUNTIF(B23:AF23, "HL")) -> HOLIDAY: 0
A19: =IF($A18="", "", "DATE") -> DATE | B19: {=IF($A18="","",LET(mNum,MONTH(1&$N$3),start,DATE($P$3,mNum,1),days,DAY(EOMONTH(start,0)),MAP(SEQUENCE(1,days,0),LAMBDA(n,UPPER(TEXT(start+n,"dd (ddd)"))))))} -> 01 (TUE) | C19: 02 (WED) | D19: 03 (THU) | E19: 04 (FRI) | F19: 05 (SAT) | G19: 06 (SUN) | H19: 07 (MON) | I19: 08 (TUE) | J19: 09 (WED) | K19: 10 (THU) | L19: 11 (FRI) | M19: 12 (SAT) | N19: 13 (SUN) | O19: 14 (MON) | P19: 15 (TUE) | Q19: 16 (WED) | R19: 17 (THU) | S19: 18 (FRI) | T19: 19 (SAT) | U19: 20 (SUN) | V19: 21 (MON) | W19: 22 (TUE) | X19: 23 (WED) | Y19: 24 (THU) | Z19: 25 (FRI) | AA19: 26 (SAT) | AB19: 27 (SUN) | AC19: 28 (MON) | AD19: 29 (TUE) | AE19: 30 (WED)
A20: =IF($A18="", "", "IN") -> IN | B20: {=IF(OR($A18="",B$5=""),"",IFNA(INDEX(DATA_LOG!$C:$C,MATCH(1,(DATA_LOG!$A:$A=$A18)*(TEXT(DATA_LOG!$B:$B,"yyyy-MM-dd")=TEXT(DATE($P$3,MONTH(1&$N$3),VALUE(LEFT(B$5,2))),"yyyy-MM-dd")),0)),""))} | C20: {=IF(OR($A18="",C$5=""),"",IFNA(INDEX(DATA_LOG!$C:$C,MATCH(1,(DATA_LOG!$A:$A=$A18)*(TEXT(DATA_LOG!$B:$B,"yyyy-MM-dd")=TEXT(DATE($P$3,MONTH(1&$N$3),VALUE(LEFT(C$5,2))),"yyyy-MM-dd")),0)),""))} | D20: {=IF(OR($A18="",D$5=""),"",IFNA(INDEX(DATA_LOG!$C:$C,MATCH(1,(DATA_LOG!$A:$A=$A18)*(TEXT(DATA_LOG!$B:$B,"yyyy-MM-dd")=TEXT(DATE($P$3,MONTH(1&$N$3),VALUE(LEFT(D$5,2))),"yyyy-MM-dd")),0)),""))} | E20: {=IF(OR($A18="",E$5=""),"",IFNA(INDEX(DATA_LOG!$C:$C,MATCH(1,(DATA_LOG!$A:$A=$A18)*(TEXT(DATA_LOG!$B:$B,"yyyy-MM-dd")=TEXT(DATE($P$3,MONTH(1&$N$3),VALUE(LEFT(E$5,2))),"yyyy-MM-dd")),0)),""))} | F20: {=IF(OR($A18="",F$5=""),"",IFNA(INDEX(DATA_LOG!$C:$C,MATCH(1,(DATA_LOG!$A:$A=$A18)*(TEXT(DATA_LOG!$B:$B,"yyyy-MM-dd")=TEXT(DATE($P$3,MONTH(1&$N$3),VALUE(LEFT(F$5,2))),"yyyy-MM-dd")),0)),""))} | G20: {=IF(OR($A18="",G$5=""),"",IFNA(INDEX(DATA_LOG!$C:$C,MATCH(1,(DATA_LOG!$A:$A=$A18)*(TEXT(DATA_LOG!$B:$B,"yyyy-MM-dd")=TEXT(DATE($P$3,MONTH(1&$N$3),VALUE(LEFT(G$5,2))),"yyyy-MM-dd")),0)),""))} | H20: {=IF(OR($A18="",H$5=""),"",IFNA(INDEX(DATA_LOG!$C:$C,MATCH(1,(DATA_LOG!$A:$A=$A18)*(TEXT(DATA_LOG!$B:$B,"yyyy-MM-dd")=TEXT(DATE($P$3,MONTH(1&$N$3),VALUE(LEFT(H$5,2))),"yyyy-MM-dd")),0)),""))} | I20: {=IF(OR($A18="",I$5=""),"",IFNA(INDEX(DATA_LOG!$C:$C,MATCH(1,(DATA_LOG!$A:$A=$A18)*(TEXT(DATA_LOG!$B:$B,"yyyy-MM-dd")=TEXT(DATE($P$3,MONTH(1&$N$3),VALUE(LEFT(I$5,2))),"yyyy-MM-dd")),0)),""))} | ... AF20: {=IF(OR($A18="",AF$5=""),"",IFNA(INDEX(DATA_LOG!$C:$C,MATCH(1,(DATA_LOG!$A:$A=$A18)*(TEXT(DATA_LOG!$B:$B,"yyyy-MM-dd")=TEXT(DATE($P$3,MONTH(1&$N$3),VALUE(LEFT(AF$5,2))),"yyyy-MM-dd")),0)),""))}
A21: =IF($A18="", "", "OUT") -> OUT | B21: {=IF(OR($A18="",B$5=""),"",IFNA(INDEX(DATA_LOG!$D:$D,MATCH(1,(DATA_LOG!$A:$A=$A18)*(TEXT(DATA_LOG!$B:$B,"yyyy-MM-dd")=TEXT(DATE($P$3,MONTH(1&$N$3),VALUE(LEFT(B$5,2))),"yyyy-MM-dd")),0)),""))} | C21: {=IF(OR($A18="",C$5=""),"",IFNA(INDEX(DATA_LOG!$D:$D,MATCH(1,(DATA_LOG!$A:$A=$A18)*(TEXT(DATA_LOG!$B:$B,"yyyy-MM-dd")=TEXT(DATE($P$3,MONTH(1&$N$3),VALUE(LEFT(C$5,2))),"yyyy-MM-dd")),0)),""))} | D21: {=IF(OR($A18="",D$5=""),"",IFNA(INDEX(DATA_LOG!$D:$D,MATCH(1,(DATA_LOG!$A:$A=$A18)*(TEXT(DATA_LOG!$B:$B,"yyyy-MM-dd")=TEXT(DATE($P$3,MONTH(1&$N$3),VALUE(LEFT(D$5,2))),"yyyy-MM-dd")),0)),""))} | E21: {=IF(OR($A18="",E$5=""),"",IFNA(INDEX(DATA_LOG!$D:$D,MATCH(1,(DATA_LOG!$A:$A=$A18)*(TEXT(DATA_LOG!$B:$B,"yyyy-MM-dd")=TEXT(DATE($P$3,MONTH(1&$N$3),VALUE(LEFT(E$5,2))),"yyyy-MM-dd")),0)),""))} | F21: {=IF(OR($A18="",F$5=""),"",IFNA(INDEX(DATA_LOG!$D:$D,MATCH(1,(DATA_LOG!$A:$A=$A18)*(TEXT(DATA_LOG!$B:$B,"yyyy-MM-dd")=TEXT(DATE($P$3,MONTH(1&$N$3),VALUE(LEFT(F$5,2))),"yyyy-MM-dd")),0)),""))} | G21: {=IF(OR($A18="",G$5=""),"",IFNA(INDEX(DATA_LOG!$D:$D,MATCH(1,(DATA_LOG!$A:$A=$A18)*(TEXT(DATA_LOG!$B:$B,"yyyy-MM-dd")=TEXT(DATE($P$3,MONTH(1&$N$3),VALUE(LEFT(G$5,2))),"yyyy-MM-dd")),0)),""))} | H21: {=IF(OR($A18="",H$5=""),"",IFNA(INDEX(DATA_LOG!$D:$D,MATCH(1,(DATA_LOG!$A:$A=$A18)*(TEXT(DATA_LOG!$B:$B,"yyyy-MM-dd")=TEXT(DATE($P$3,MONTH(1&$N$3),VALUE(LEFT(H$5,2))),"yyyy-MM-dd")),0)),""))} | I21: {=IF(OR($A18="",I$5=""),"",IFNA(INDEX(DATA_LOG!$D:$D,MATCH(1,(DATA_LOG!$A:$A=$A18)*(TEXT(DATA_LOG!$B:$B,"yyyy-MM-dd")=TEXT(DATE($P$3,MONTH(1&$N$3),VALUE(LEFT(I$5,2))),"yyyy-MM-dd")),0)),""))} | ... AF21: {=IF(OR($A18="",AF$5=""),"",IFNA(INDEX(DATA_LOG!$D:$D,MATCH(1,(DATA_LOG!$A:$A=$A18)*(TEXT(DATA_LOG!$B:$B,"yyyy-MM-dd")=TEXT(DATE($P$3,MONTH(1&$N$3),VALUE(LEFT(AF$5,2))),"yyyy-MM-dd")),0)),""))}
A22: =IF($A18="", "", "TOTAL") -> TOTAL | B22: =IF(OR(B20="",B21=""),"",B21-B20) | C22: =IF(OR(C20="",C21=""),"",C21-C20) | D22: =IF(OR(D20="",D21=""),"",D21-D20) | E22: =IF(OR(E20="",E21=""),"",E21-E20) | F22: =IF(OR(F20="",F21=""),"",F21-F20) | G22: =IF(OR(G20="",G21=""),"",G21-G20) | H22: =IF(OR(H20="",H21=""),"",H21-H20) | I22: =IF(OR(I20="",I21=""),"",I21-I20) | ... AF22: =IF(OR(AF20="",AF21=""),"",AF21-AF20)
